Workbook

Sheet Calculator
A1: Vector 3D Califlower
A2: Measurements
A3: (This spreadsheet is locked to prevent accidental modification)
B4: Scale | C4: 1
B5: (if you have a larger printer, and larger tools, you can print at larger scale)
B7: Reading 1 | C7: Reading 2 | D7: Reading 3 | E7: Average
A8: 1 | B8: 99.8 | C8: 99.8 | D8: 99.8 | E8: =AVERAGE(B8:D8) -> 99.8
A9: 2 | B9: 49.87 | C9: 49.88 | D9: 49.88 | E9: =AVERAGE(B9:D9) -> 49.876667
A10: 3 | B10: 99.88 | C10: 99.9 | D10: 99.96 | E10: =AVERAGE(B10:D10) -> 99.913333
A11: 4 | B11: 49.99 | C11: 49.98 | D11: 49.97 | E11: =AVERAGE(B11:D11) -> 49.98
A12: 5 | B12: 99.92 | C12: 99.88 | D12: 99.89 | E12: =AVERAGE(B12:D12) -> 99.896667
A13: 6 | B13: 49.96 | C13: 49.98 | D13: 49.98 | E13: =AVERAGE(B13:D13) -> 49.973333
A14: 7 | B14: 99.98 | C14: 99.96 | D14: 99.96 | E14: =AVERAGE(B14:D14) -> 99.966667
A15: 8 | B15: 49.98 | C15: 49.97 | D15: 49.98 | E15: =AVERAGE(B15:D15) -> 49.976667
A16: 9 | B16: 99.83 | C16: 99.73 | D16: 99.75 | E16: =AVERAGE(B16:D16) -> 99.77
A17: 10 | B17: 99.76 | C17: 99.76 | D17: 99.77 | E17: =AVERAGE(B17:D17) -> 99.763333
B19: Green | C19: <1mm deviation. Measurement seems ok. Continue.
B20: Yellow | C20: >1mm deviation warning. Double-check your measurement.
B21: Red | C21: >5mm deviation warning. Steps/mm or large measurement error.
A23: Results | G23: What the Results Mean
B24: Error | C24: Correction | G24: If X and Y errors are both negative, your print is undersize by the percentage shown.
A25: X | B25: =Data!B13 -> -0.0014333333 | C25: =B25*-1 -> 0.0014333333 | G25: If X and Y errors are both positive, your print is oversize by the percentage shown.
A26: Y | B26: =Data!C13 -> -0.00059166667 | C26: =B26*-1 -> 0.00059166667 | G26: If X and Y errors are very different from each other, check your steps/mm and belt tension.
G27: If you have CoreXY, X and Y are 'locked' to each other so use the average of the two errors.
B28: Measured | C28: Correction | G28: For X and Y see 'Fix Size' below. For skew see 'Fix Skew'
A29: Angle | B29: =Data!B19 -> 89.996171 | G29: Inner and Outer errors are averages that include X and Y dimensions that may be useful to diagnose over/under extrusion.
A30: Skew | B30: =Data!B20 -> -0.0038286584 | C30: =-B30 -> 0.0038286584 | G30: If inner is negative, and outer is positive, this could indicate over extrusion.
G31: If inner is positive, and outer is negative, this could indicate under extrusion.
B32: Measured | C32: Correction
A33: Inner | B33: =Data!D13 -> -0.00051666667 | C33: =B33*-1 -> 0.00051666667 | G33: Tips For Implementation
A34: Outer | B34: =Data!E13 -> -0.0015083333 | C34: =B34*-1 -> 0.0015083333 | G34: Ensure you have calibration Extuder Step/mm before doing this test.
G35: Ensure you have XYZ Steps/mm set approximately correct before doing this test.
A36: Fix Skew | G36: If you have quite large skew error (>0.5°), correct this first before doing XY scale compensation.
A37: Note: Because of the way excel works, you may find "," and "." get switched for your regional language settings. | G37: Superslicer is the only slicer with Material XY Shrinkage compensation. If you use Cura, PS, ideamaker etc you will have to use steps/mm (or rotation distance) for the printer instead, or remember to scale the print for different materials
A38: Klipper G Code Fix
B40: Add | C40: [skew_correction] | E40: to printer.cfg
B41: Send Command | C41: =Data!A23 -> SET_SKEW XY=99.77,99.76,70.61 | E41: via console
B42: Send Command | C42: =Data!A24 -> SKEW_PROFILE SAVE=CaliFlower | E42: via console
B43: Send Command | C43: SAVE_CONFIG | E43: via console
B44: Add | C44: SKEW_PROFILE LOAD=CaliFlower | E44: to end of start G code
...

Sheet Data
B1: Design | C1: % Error
A2: 1 | B2: =100*scale -> 100 | C2: =(Calculator!E8-Data!B2)/B2 -> -0.002
A3: 2 | B3: =50*scale -> 50 | C3: =(Calculator!E9-Data!B3)/B3 -> -0.0024666667
A4: 3 | B4: =100*scale -> 100 | C4: =(Calculator!E10-Data!B4)/B4 -> -0.00086666667
A5: 4 | B5: =50*scale -> 50 | C5: =(Calculator!E11-Data!B5)/B5 -> -0.0004
A6: 5 | B6: =100*scale -> 100 | C6: =(Calculator!E12-Data!B6)/B6 -> -0.0010333333
A7: 6 | B7: =50*scale -> 50 | C7: =(Calculator!E13-Data!B7)/B7 -> -0.00053333333
A8: 7 | B8: =100*scale -> 100 | C8: =(Calculator!E14-Data!B8)/B8 -> -0.00033333333
A9: 8 | B9: =50*scale -> 50 | C9: =(Calculator!E15-Data!B9)/B9 -> -0.00046666667
B12: X | C12: Y | D12: Inner | E12: Outer
A13: Average | B13: =AVERAGE(C2:C5) -> -0.0014333333 | C13: =AVERAGE(C6:C9) -> -0.00059166667 | D13: =AVERAGE(C4:C5,C8:C9) -> -0.00051666667 | E13: =AVERAGE(C2:C3,C6:C7) -> -0.0015083333
A17: H1 (a) | B17: =50*SQRT(2)*(1+B13)*Calculator!C4 -> 70.609326
A18: H2 (b) | B18: =SQRT(((Calculator!E16^2)+(Calculator!E17^2)-2*(B17^2))/2) -> 70.48199
A19: Angle | B19: =DEGREES(ACOS(((Calculator!E16^2)-(B17^2)-(B18^2))/(2*B17*B18))) -> 89.996171
A20: Skew | B20: =B19-90 -> -0.0038286584
A22: Klipper
A23: ="SET_SKEW XY="&ROUND(Calculator!E16,2)&","&ROUND(Calculator!E17,2)&","&ROUND(B17,2) -> SET_SKEW XY=99.77,99.76,70.61
A24: SKEW_PROFILE SAVE=CaliFlower
A25: GET_CURRENT_SKEW
A27: Marlin
A28: if ENABLED(SKEW_CORRECTION)
A29: =" define XY_DIAG_AC " & ROUND(Calculator!E16,4) -> define XY_DIAG_AC 99.77
A30: =" define XY_DIAG_BD " & ROUND(Calculator!E17,4) -> define XY_DIAG_BD 99.7633
A31: =" define XY_SIDE_AD "&ROUND(B17,4) -> define XY_SIDE_AD 70.6093
A32: =IFERROR(" define XY_SKEW_FACTOR " & ROUND(B37,6),"ERROR") -> define XY_SKEW_FACTOR -0.002576
A34: AC | B34: =Calculator!E16 -> 99.77 | F34: From Marlin Firmware:
A35: AB | B35: =50*SQRT(2)*(1+C13)*Calculator!C4 -> 70.668841 | F35: Compute AB : SQRT(2*AC*AC+2*BD*BD-4*AD*AD)/2
A36: AD | B36: =B17 -> 70.609326 | F36: XY_SKEW_FACTOR : TAN(PI/2-ACOS((AC*AC-AB*AB-AD*AD)/(2*AB*AD)))
A37: Skew Factor | B37: =IFERROR(TAN(PI()/2-ACOS(((B34^2)-(B35^2)-(B36^2))/(2*B35*B36))),"ERROR") -> -0.0025761353
A39: Marlin G Code
B40: #define SKEW_CORRECTION_GCODE
A41: G Code | B41: ="M852 I"&ROUND(B37,6) -> M852 I-0.002576 | F41: More info on Marlin EEPROM
A42: EEPROM | B42: M500 | F42: https://marlinfw.org/docs/features/eeprom.html
A44: RRF
A45: Example | B45: M556 S100 X0.7 Y-0.2 Z0.6 | F45: X value is XY compensation, others involve Z
A46: Value | B46: =100*TAN(RADIANS(B19-90)) -> -0.0066822695
A47: ="M556 S100 X"& ROUND(B46,3) -> M556 S100 X-0.007
A49: Bambu Firmware
A51: Skew | B51: ="M1005 X" & ROUND(Calculator!E16,3) & " Y" & ROUND(Calculator!E17,3) -> M1005 X99.77 Y99.763
A52: Reset | B52: M1005 I0
...
